Workbook
Name arco10okff: '[1]TOK FF Pvp'!$A$405:$U$434
Name arco10okpr: '[1]TOK PRE'!$A$295:$U$323
Name arco11okff: '[1]TOK FF Pvp'!$A$445:$U$474
Name arco11okpr: '[1]TOK PRE'!$A$324:$U$352
Name arco12okff: '[1]TOK FF Pvp'!$A$485:$U$514
Name arco12okpr: '[1]TOK PRE'!$A$353:$U$381
Name arco13okff: '[1]TOK FF Pvp'!$A$525:$U$554
Name arco13okpr: '[1]TOK PRE'!$A$382:$U$410
Name arco14okff: '[1]TOK FF Pvp'!$A$565:$U$594
Name arco14okpr: '[1]TOK PRE'!$A$411:$U$439
Name arco15okff: '[1]TOK FF Pvp'!$A$605:$U$634
Name arco15okpr: '[1]TOK PRE'!$A$440:$U$468
Name arco16okff: '[1]TOK FF Pvp'!$A$645:$U$674
Name arco16okpr: '[1]TOK PRE'!$A$469:$U$497
Name arco17okff: '[1]TOK FF Pvp'!$A$685:$U$714
Name arco17okpr: '[1]TOK PRE'!$A$498:$U$526
Name arco18okff: '[1]TOK FF Pvp'!$A$725:$U$754
Name arco18okfr: '[1]TOK FR'!#REF!
Name arco18okpr: '[1]TOK PRE'!$A$527:$U$555
Name arco1okff: '[1]TOK FF Pvp'!$A$45:$U$74
Name arco1okfr: '[1]TOK FR'!$A$38:$U$68
Name arco1okpr: '[1]TOK PRE'!$A$34:$U$63
Name arco20okff: #REF!
Name arco2okff: '[1]TOK FF Pvp'!$A$85:$U$114
Name arco2okfr: '[1]TOK FR'!$A$70:$U$100
Name arco2okpr: '[1]TOK PRE'!$A$63:$U$91
Name arco3okff: '[1]TOK FF Pvp'!$A$125:$U$154
Name arco3okfr: '[1]TOK FR'!$A$102:$U$132
Name arco3okpr: '[1]TOK PRE'!$A$92:$U$120
Name arco4okff: '[1]TOK FF Pvp'!$A$165:$U$194
Name arco4okfr: '[1]TOK FR'!$A$134:$U$164
Name arco4okpr: '[1]TOK PRE'!$A$121:$U$149
Name arco5okff: '[1]TOK FF Pvp'!$A$205:$U$234
Name arco5okpr: '[1]TOK PRE'!$A$150:$U$178
Name arco6okff: '[1]TOK FF Pvp'!$A$245:$U$274
Name arco6okpr: '[1]TOK PRE'!$A$179:$U$207
Name arco7okff: '[1]TOK FF Pvp'!$A$285:$U$314
Name arco7okpr: '[1]TOK PRE'!$A$208:$U$236
Name arco8okff: '[1]TOK FF Pvp'!$A$325:$U$354
Name arco8okpr: '[1]TOK PRE'!$A$237:$U$265
Name arco9okff: '[1]TOK FF Pvp'!$A$365:$U$394
Name arco9okpr: '[1]TOK PRE'!$A$266:$U$294
Name categorias_web: [1]WEB!$A$4:$D$96
Name costarco10webfrnr: '[1]-COST-BREAK WEB FR NR'!$B$811:$BB$900
Name costarco10webnr: '[1]COST-BREAK WEB NR'!$B$847:$BB$940
Name costarco11webfrnr: '[1]-COST-BREAK WEB FR NR'!$B$901:$BB$990
Name costarco11webnr: '[1]COST-BREAK WEB NR'!$B$941:$BB$1034
Name costarco12webfrnr: '[1]-COST-BREAK WEB FR NR'!$B$991:$BB$1080
Name costarco12webnr: '[1]COST-BREAK WEB NR'!$B$1035:$BB$1128
Name costarco13webfrnr: '[1]-COST-BREAK WEB FR NR'!$B$1081:$BB$1170
Name costarco13webnr: '[1]COST-BREAK WEB NR'!$B$1129:$BB$1222
Name costarco14webfrnr: '[1]-COST-BREAK WEB FR NR'!$B$1171:$BB$1260
Name costarco14webnr: '[1]COST-BREAK WEB NR'!$B$1223:$BB$1316
Name costarco15webfrnr: '[1]-COST-BREAK WEB FR NR'!$B$1261:$BB$1350
Name costarco15webnr: '[1]COST-BREAK WEB NR'!$B$1317:$BB$1410
Name costarco16webfrnr: '[1]-COST-BREAK WEB FR NR'!$B$1351:$BB$1440
Name costarco16webnr: '[1]COST-BREAK WEB NR'!$B$1411:$BB$1504
Name costarco17webfrnr: '[1]-COST-BREAK WEB FR NR'!$B$1441:$BB$1530
Name costarco17webnr: '[1]COST-BREAK WEB NR'!$B$1505:$BB$1598
Name costarco18webfrnr: '[1]-COST-BREAK WEB FR NR'!$B$1531:$BB$1620

Sheet PRICING
B1: Length of rental | D1: 7 DAYS | F1: ATTENTION: These prices will be established for the Full/Full rate for reservation of 7 rental days, as retail price, so they must include VAT.
B2: Rate type | D2: F/F
B3: Statio | D3: TUN
B5: DATE | D5: DATE | F5: DATE | H5: DATE | J5: DATE | L5: DATE | N5: DATE | P5: DATE | R5: DATE | T5: DATE | V5: DATE | X5: DATE | Z5: DATE | AB5: DATE | AD5: DATE | AF5: DATE | AH5: DATE | AJ5: DATE | AL5: DATE | AN5: DATE | AP5: DATE | AR5: DATE | AT5: DATE | AV5: DATE | AX5: DATE | AZ5: DATE | BB5: DATE | BD5: DATE | BF5: DATE | BH5: DATE
B6: 45972 | D6: 45973 | F6: 45986 | H6: 46000 | J6: 46002 | L6: 46006 | N6: 46007 | P6: 46011 | R6: 46023 | T6: 46024 | V6: 46025 | X6: 46027 | Z6: 46028 | AB6: 46033 | AD6: 46035 | AF6: 46036 | AH6: 46037 | AJ6: 46095 | AL6: 46097 | AN6: 46113 | AP6: 46147 | AR6: 46165 | AT6: 46175 | AV6: 46181
B7: 45972 | D7: 45985 | F7: 45999 | H7: 46001 | J7: 46005 | L7: 46006 | N7: 46010 | P7: 46022 | R7: 46023 | T7: 46024 | V7: 46026 | X7: 46027 | Z7: 46032 | AB7: 46034 | AD7: 46035 | AF7: 46036 | AH7: 46094 | AJ7: 46096 | AL7: 46112 | AN7: 46146 | AP7: 46164 | AR7: 46174 | AT7: 46180 | AV7: 46181
A8: ESMS | B8: 170.17 | C8: %INCREASE | D8: 170.17 | E8: %INCREASE | F8: 170.17 | G8: %INCREASE | H8: 170.17 | I8: %INCREASE | J8: 187.11 | K8: %INCREASE | L8: 187.11 | M8: %INCREASE | N8: 254.87 | O8: %INCREASE | P8: 254.87 | Q8: %INCREASE | R8: 254.87 | S8: %INCREASE | T8: 254.87 | U8: %INCREASE | V8: 254.87 | W8: %INCREASE | X8: 254.87 | Y8: %INCREASE | Z8: 254.87 | AA8: %INCREASE | AB8: 254.87 | AC8: %INCREASE | AD8: 254.87 | AE8: %INCREASE | AF8: 245.63 | AG8: %INCREASE | AH8: 245.63 | AI8: %INCREASE | AJ8: 245.63 | AK8: %INCREASE | AL8: 245.63 | AM8: %INCREASE | AN8: 264.11 | AO8: %INCREASE | AP8: 264.11 | AQ8: %INCREASE | AR8: 264.11 | AS8: %INCREASE | AT8: 355.74 | AU8: %INCREASE | AV8: 355.74 | AW8: %INCREASE | AY8: %INCREASE | BA8: %INCREASE | BC8: %INCREASE | BE8: %INCREASE | BG8: %INCREASE | BI8: %INCREASE
A9: EMMS | B9: 178.64 | C9: 0.049773756 | D9: 178.64 | E9: 0.049773756 | F9: 178.64 | G9: 0.049773756 | H9: 178.64 | I9: 0.049773756 | J9: 196.35 | K9: 0.049382716 | L9: 229.46 | M9: 0.22633745 | N9: 229.46 | O9: -0.099697885 | P9: 229.46 | Q9: -0.099697885 | R9: 229.46 | S9: -0.099697885 | T9: 229.46 | U9: -0.099697885 | V9: 229.46 | W9: -0.099697885 | X9: 229.46 | Y9: -0.099697885 | Z9: 214.06 | AA9: -0.16012085 | AB9: 224.07 | AC9: -0.12084592 | AD9: 224.07 | AE9: -0.12084592 | AF9: 224.07 | AG9: -0.087774295 | AH9: 224.07 | AI9: -0.087774295 | AJ9: 224.07 | AK9: -0.087774295 | AL9: 224.07 | AM9: -0.087774295 | AN9: 224.07 | AO9: -0.1516035 | AP9: 224.07 | AQ9: -0.1516035 | AR9: 224.07 | AS9: -0.1516035 | AT9: 224.07 | AU9: -0.37012987 | AV9: 224.07 | AW9: -0.37012987 | AX9: =($AX$8*(1+AY9)) -> 0 | AY9: 0 | AZ9: =($AZ$8*(1+BA9)) -> 0 | BA9: 0 | BB9: =($BB$8*(1+BC9)) -> 0 | BC9: 0 | BD9: =($BD$8*(1+BE9)) -> 0 | BE9: 0 | BF9: =($BF$8*(1+BG9)) -> 0 | BG9: 0 | BH9: =($BH$8*(1+BI9)) -> 0 | BI9: 0
A10: PSMS | B10: 177.87 | C10: 0.045248869 | D10: 177.87 | E10: 0.045248869 | F10: 177.87 | G10: 0.045248869 | H10: 177.87 | I10: 0.045248869 | J10: 195.58 | K10: 0.04526749 | L10: 195.58 | M10: 0.04526749 | N10: 472.78 | O10: 0.85498489 | P10: 472.78 | Q10: 0.85498489 | R10: 357.28 | S10: 0.40181269 | T10: 357.28 | U10: 0.40181269 | V10: 357.28 | W10: 0.40181269 | X10: 357.28 | Y10: 0.40181269 | Z10: 357.28 | AA10: 0.40181269 | AB10: 373.45 | AC10: 0.4652568 | AD10: 373.45 | AE10: 0.4652568 | AF10: 373.45 | AG10: 0.52037618 | AH10: 373.45 | AI10: 0.52037618 | AJ10: 373.45 | AK10: 0.52037618 | AL10: 546.7 | AM10: 1.2257053 | AN10: 546.7 | AO10: 1.0699708 | AP10: 546.7 | AQ10: 1.0699708 | AR10: 546.7 | AS10: 1.0699708 | AT10: 599.06 | AU10: 0.68398268 | AV10: 599.06 | AW10: 0.68398268 | AX10: =($AX$8*(1+AY10)) -> 0 | AY10: 0 | AZ10: =($AZ$8*(1+BA10)) -> 0 | BA10: 0 | BB10: =($BB$8*(1+BC10)) -> 0 | BC10: 0 | BD10: =($BD$8*(1+BE10)) -> 0 | BE10: 0 | BF10: =($BF$8*(1+BG10)) -> 0 | BG10: 0 | BH10: =($BH$8*(1+BI10)) -> 0 | BI10: 0
A11: SSMS | B11: 270.27 | C11: 0.58823529 | D11: 270.27 | E11: 0.58823529 | F11: 270.27 | G11: 0.58823529 | H11: 270.27 | I11: 0.58823529 | J11: 297.22 | K11: 0.58847737 | L11: 297.22 | M11: 0.58847737 | N11: 574.42 | O11: 1.2537764 | P11: 574.42 | Q11: 1.2537764 | R11: 574.42 | S11: 1.2537764 | T11: 431.97 | U11: 0.69486405 | V11: 431.97 | W11: 0.69486405 | X11: 431.97 | Y11: 0.69486405 | Z11: 431.97 | AA11: 0.69486405 | AB11: 451.99 | AC11: 0.7734139 | AD11: 451.99 | AE11: 0.7734139 | AF11: 451.99 | AG11: 0.84012539 | AH11: 451.99 | AI11: 0.84012539 | AJ11: 451.99 | AK11: 0.84012539 | AL11: 451.99 | AM11: 0.84012539 | AN11: 451.99 | AO11: 0.71137026 | AP11: 451.99 | AQ11: 0.71137026 | AR11: 451.99 | AS11: 0.71137026 | AT11: 761.53 | AU11: 1.1406926 | AV11: 761.53 | AW11: 1.1406926 | AX11: =($AX$8*(1+AY11)) -> 0 | AY11: 0 | AZ11: =($AZ$8*(1+BA11)) -> 0 | BA11: 0 | BB11: =($BB$8*(1+BC11)) -> 0 | BC11: 0 | BD11: =($BD$8*(1+BE11)) -> 0 | BE11: 0 | BF11: =($BF$8*(1+BG11)) -> 0 | BG11: 0 | BH11: =($BH$8*(1+BI11)) -> 0 | BI11: 0
A12: PMMS | B12: 228.69 | C12: 0.3438914 | D12: 228.69 | E12: 0.3438914 | F12: 228.69 | G12: 0.3438914 | H12: 228.69 | I12: 0.3438914 | J12: 272.58 | K12: 0.45679012 | L12: 272.58 | M12: 0.45679012 | N12: 272.58 | O12: 0.069486405 | P12: 272.58 | Q12: 0.069486405 | R12: 272.58 | S12: 0.069486405 | T12: 272.58 | U12: 0.069486405 | V12: 272.58 | W12: 0.069486405 | X12: 272.58 | Y12: 0.069486405 | Z12: 272.58 | AA12: 0.069486405 | AB12: 272.58 | AC12: 0.069486405 | AD12: 272.58 | AE12: 0.069486405 | AF12: 263.34 | AG12: 0.072100313 | AH12: 263.34 | AI12: 0.072100313 | AJ12: 263.34 | AK12: 0.072100313 | AL12: 263.34 | AM12: 0.072100313 | AN12: 497.42 | AO12: 0.88338192 | AP12: 497.42 | AQ12: 0.88338192 | AR12: 497.42 | AS12: 0.88338192 | AT12: 835.45 | AU12: 1.3484848 | AV12: 835.45 | AW12: 1.3484848 | AX12: =($AX$8*(1+AY12)) -> 0 | AY12: 0 | AZ12: =($AZ$8*(1+BA12)) -> 0 | BA12: 0 | BB12: =($BB$8*(1+BC12)) -> 0 | BC12: 0 | BD12: =($BD$8*(1+BE12)) -> 0 | BE12: 0 | BF12: =($BF$8*(1+BG12)) -> 0 | BG12: 0 | BH12: =($BH$8*(1+BI12)) -> 0 | BI12: 0
A13: EMAS | B13: 275.66 | C13: 0.6199095 | D13: 275.66 | E13: 0.6199095 | F13: 275.66 | G13: 0.6199095 | H13: 275.66 | I13: 0.6199095 | J13: 322.63 | K13: 0.72427984 | L13: 322.63 | M13: 0.72427984 | N13: 322.63 | O13: 0.26586103 | P13: 518.98 | Q13: 1.0362538 | R13: 537.46 | S13: 1.1087613 | T13: 537.46 | U13: 1.1087613 | V13: 329.56 | W13: 0.29305136 | X13: 329.56 | Y13: 0.29305136 | Z13: 329.56 | AA13: 0.29305136 | AB13: 329.56 | AC13: 0.29305136 | AD13: 321.09 | AE13: 0.25981873 | AF13: 321.09 | AG13: 0.30721003 | AH13: 313.39 | AI13: 0.27586207 | AJ13: 313.39 | AK13: 0.27586207 | AL13: 313.39 | AM13: 0.27586207 | AN13: 564.41 | AO13: 1.1370262 | AP13: 508.2 | AQ13: 0.92419825 | AR13: 562.1 | AS13: 1.1282799 | AT13: 562.1 | AU13: 0.58008658 | AV13: 508.2 | AW13: 0.42857143 | AX13: =($AX$8*(1+AY13)) -> 0 | AY13: 0 | AZ13: =($AZ$8*(1+BA13)) -> 0 | BA13: 0 | BB13: =($BB$8*(1+BC13)) -> 0 | BC13: 0 | BD13: =($BD$8*(1+BE13)) -> 0 | BE13: 0 | BF13: =($BF$8*(1+BG13)) -> 0 | BG13: 0 | BH13: =($BH$8*(1+BI13)) -> 0 | BI13: 0
A14: PSAS | B14: 279.51 | C14: 0.64253394 | D14: 279.51 | E14: 0.64253394 | F14: 279.51 | G14: 0.64253394 | H14: 279.51 | I14: 0.64253394 | J14: 305.69 | K14: 0.63374486 | L14: 305.69 | M14: 0.63374486 | N14: 305.69 | O14: 0.19939577 | P14: 305.69 | Q14: 0.19939577 | R14: 305.69 | S14: 0.19939577 | T14: 305.69 | U14: 0.19939577 | V14: 305.69 | W14: 0.19939577 | X14: 305.69 | Y14: 0.19939577 | Z14: 305.69 | AA14: 0.19939577 | AB14: 305.69 | AC14: 0.19939577 | AD14: 305.69 | AE14: 0.19939577 | AF14: 305.69 | AG14: 0.24451411 | AH14: 305.69 | AI14: 0.24451411 | AJ14: 305.69 | AK14: 0.24451411 | AL14: 305.69 | AM14: 0.24451411 | AN14: 305.69 | AO14: 0.1574344 | AP14: 305.69 | AQ14: 0.1574344 | AR14: 305.69 | AS14: 0.1574344 | AT14: 305.69 | AU14: -0.14069264 | AV14: 305.69 | AW14: -0.14069264 | AX14: =($AX$8*(1+AY14)) -> 0 | AY14: 0 | AZ14: =($AZ$8*(1+BA14)) -> 0 | BA14: 0 | BB14: =($BB$8*(1+BC14)) -> 0 | BC14: 0 | BD14: =($BD$8*(1+BE14)) -> 0 | BE14: 0 | BF14: =($BF$8*(1+BG14)) -> 0 | BG14: 0 | BH14: =($BH$8*(1+BI14)) -> 0 | BI14: 0
A15: SSAS | B15: 434.28 | C15: 1.5520362 | D15: 423.5 | E15: 1.4886878 | F15: 397.32 | G15: 1.3348416 | H15: 388.08 | I15: 1.280543 | J15: 426.58 | K15: 1.2798354 | L15: 426.58 | M15: 1.2798354 | N15: 655.27 | O15: 1.570997 | P15: 655.27 | Q15: 1.570997 | R15: 655.27 | S15: 1.570997 | T15: 492.03 | U15: 0.9305136 | V15: 492.03 | W15: 0.9305136 | X15: 492.03 | Y15: 0.9305136 | Z15: 492.03 | AA15: 0.9305136 | AB15: 514.36 | AC15: 1.0181269 | AD15: 514.36 | AE15: 1.0181269 | AF15: 514.36 | AG15: 1.0940439 | AH15: 514.36 | AI15: 1.0940439 | AJ15: 514.36 | AK15: 1.0940439 | AL15: 514.36 | AM15: 1.0940439 | AN15: 514.36 | AO15: 0.94752187 | AP15: 514.36 | AQ15: 0.94752187 | AR15: 514.36 | AS15: 0.94752187 | AT15: 868.56 | AU15: 1.4415584 | AV15: 868.56 | AW15: 1.4415584 | AX15: =($AX$8*(1+AY15)) -> 0 | AY15: 0 | AZ15: =($AZ$8*(1+BA15)) -> 0 | BA15: 0 | BB15: =($BB$8*(1+BC15)) -> 0 | BC15: 0 | BD15: =($BD$8*(1+BE15)) -> 0 | BE15: 0 | BF15: =($BF$8*(1+BG15)) -> 0 | BG15: 0 | BH15: =($BH$8*(1+BI15)) -> 0 | BI15: 0
A16: PMAS | B16: 510.51 | C16: 2 | D16: 510.51 | E16: 2 | F16: 510.51 | G16: 2 | H16: 510.51 | I16: 2 | J16: 561.33 | K16: 2 | L16: 561.33 | M16: 2 | N16: 764.61 | O16: 2 | P16: 764.61 | Q16: 2 | R16: 764.61 | S16: 2 | T16: 764.61 | U16: 2 | V16: 764.61 | W16: 2 | X16: 764.61 | Y16: 2 | Z16: 764.61 | AA16: 2 | AB16: 764.61 | AC16: 2 | AD16: 764.61 | AE16: 2 | AF16: 736.89 | AG16: 2 | AH16: 736.89 | AI16: 2 | AJ16: 736.89 | AK16: 2 | AL16: 736.89 | AM16: 2 | AN16: 792.33 | AO16: 2 | AP16: 792.33 | AQ16: 2 | AR16: 792.33 | AS16: 2 | AT16: 1067.22 | AU16: 2 | AV16: 1067.22 | AW16: 2 | AX16: =($AX$8*(1+AY16)) -> 0 | AY16: 0 | AZ16: =($AZ$8*(1+BA16)) -> 0 | BA16: 0 | BB16: =($BB$8*(1+BC16)) -> 0 | BC16: 0 | BD16: =($BD$8*(1+BE16)) -> 0 | BE16: 0 | BF16: =($BF$8*(1+BG16)) -> 0 | BG16: 0 | BH16: =($BH$8*(1+BI16)) -> 0 | BI16: 0
A17: CMAS | B17: 592.13 | C17: 2.479638 | D17: 575.96 | E17: 2.3846154 | F17: 542.08 | G17: 2.1855204 | H17: 528.99 | I17: 2.1085973 | J17: 582.12 | K17: 2.1111111 | L17: 582.12 | M17: 2.1111111 | N17: 774.62 | O17: 2.0392749 | P17: 858.55 | Q17: 2.3685801 | R17: 858.55 | S17: 2.3685801 | T17: 671.44 | U17: 1.6344411 | V17: 671.44 | W17: 1.6344411 | X17: 671.44 | Y17: 1.6344411 | Z17: 671.44 | AA17: 1.6344411 | AB17: 702.24 | AC17: 1.755287 | AD17: 702.24 | AE17: 1.755287 | AF17: 702.24 | AG17: 1.8589342 | AH17: 702.24 | AI17: 1.8589342 | AJ17: 702.24 | AK17: 1.8589342 | AL17: 702.24 | AM17: 1.8589342 | AN17: 702.24 | AO17: 1.6588921 | AP17: 702.24 | AQ17: 1.6588921 | AR17: 702.24 | AS17: 1.6588921 | AT17: 897.82 | AU17: 1.5238095 | AV17: 810.04 | AW17: 1.2770563 | AX17: =($AX$8*(1+AY17)) -> 0 | AY17: 0 | AZ17: =($AZ$8*(1+BA17)) -> 0 | BA17: 0 | BB17: =($BB$8*(1+BC17)) -> 0 | BC17: 0 | BD17: =($BD$8*(1+BE17)) -> 0 | BE17: 0 | BF17: =($BF$8*(1+BG17)) -> 0 | BG17: 0 | BH17: =($BH$8*(1+BI17)) -> 0 | BI17: 0
A18: SMAS | B18: 680.68 | C18: 3 | D18: 680.68 | E18: 3 | F18: 680.68 | G18: 3 | H18: 680.68 | I18: 3 | J18: 748.44 | K18: 3 | L18: 748.44 | M18: 3 | N18: 1019.48 | O18: 3 | P18: 1019.48 | Q18: 3 | R18: 1019.48 | S18: 3 | T18: 1019.48 | U18: 3 | V18: 1019.48 | W18: 3 | X18: 1019.48 | Y18: 3 | Z18: 1019.48 | AA18: 3 | AB18: 1019.48 | AC18: 3 | AD18: 1019.48 | AE18: 3 | AF18: 982.52 | AG18: 3 | AH18: 982.52 | AI18: 3 | AJ18: 982.52 | AK18: 3 | AL18: 982.52 | AM18: 3 | AN18: 1056.44 | AO18: 3 | AP18: 1056.44 | AQ18: 3 | AR18: 1056.44 | AS18: 3 | AT18: 1422.96 | AU18: 3 | AV18: 1422.96 | AW18: 3 | AX18: =($AX$8*(1+AY18)) -> 0 | AY18: 0 | AZ18: =($AZ$8*(1+BA18)) -> 0 | BA18: 0 | BB18: =($BB$8*(1+BC18)) -> 0 | BC18: 0 | BD18: =($BD$8*(1+BE18)) -> 0 | BE18: 0 | BF18: =($BF$8*(1+BG18)) -> 0 | BG18: 0 | BH18: =($BH$8*(1+BI18)) -> 0 | BI18: 0

Sheet RESERVE LENGTH
A1: =PRICING!B6 -> 0 | B1: 1 day | C1: 2 day | D1: 3 day | E1: 4 day | F1: 5 day | G1: 6 day | H1: 7 day | I1: 8 day | J1: 9 day | K1: 10 day | L1: 11 day | M1: 12 day | N1: 13 day | O1: 14 day | P1: 15 day
A2: =PRICING!B7 -> 0 | B2: 1.75 | C2: 1.51 | D2: 1.42 | E2: 1 | F2: 1 | G2: 1 | H2: 1 | I2: 1 | J2: 1 | K2: 1 | L2: 1 | M2: 1 | N2: 1 | O2: 1 | P2: 1
A3: =PRICING!A8 -> ESMS | B3: =($H3/7)*$B$2 -> 0 | C3: =($H3/7)*2*$C$2 -> 0 | D3: =($H3/7)*3*$D$2 -> 0 | E3: =($H3/7)*4*$E$2 -> 0 | F3: =($H3/7)*5*$F$2 -> 0 | G3: =($H3/7)*6*$G$2 -> 0 | H3: =VLOOKUP(A3,PRICING!$A$8:$BI$31,2,FALSE) -> 0 | I3: =($H3/7)*8*$I$2 -> 0 | J3: =($H3/7)*9*$J$2 -> 0 | K3: =($H3/7)*10*$K$2 -> 0 | L3: =($H3/7)*11*$L$2 -> 0 | M3: =($H3/7)*12*$M$2 -> 0 | N3: =($H3/7)*13*$N$2 -> 0 | O3: =($H3/7)*14*$O$2 -> 0 | P3: =($H3/7)*15*$P$2 -> 0
A4: =PRICING!A9 -> EMMS | B4: =($H4/7)*$B$2 -> 0 | C4: =($H4/7)*2*$C$2 -> 0 | D4: =($H4/7)*3*$D$2 -> 0 | E4: =($H4/7)*4*$E$2 -> 0 | F4: =($H4/7)*5*$F$2 -> 0 | G4: =($H4/7)*6*$G$2 -> 0 | H4: =VLOOKUP(A4,PRICING!$A$8:$BI$31,2,FALSE) -> 0 | I4: =($H4/7)*8*$I$2 -> 0 | J4: =($H4/7)*9*$J$2 -> 0 | K4: =($H4/7)*10*$K$2 -> 0 | L4: =($H4/7)*11*$L$2 -> 0 | M4: =($H4/7)*12*$M$2 -> 0 | N4: =($H4/7)*13*$N$2 -> 0 | O4: =($H4/7)*14*$O$2 -> 0 | P4: =($H4/7)*15*$P$2 -> 0
A5: =PRICING!A10 -> PSMS | B5: =($H5/7)*$B$2 -> 0 | C5: =($H5/7)*2*$C$2 -> 0 | D5: =($H5/7)*3*$D$2 -> 0 | E5: =($H5/7)*4*$E$2 -> 0 | F5: =($H5/7)*5*$F$2 -> 0 | G5: =($H5/7)*6*$G$2 -> 0 | H5: =VLOOKUP(A5,PRICING!$A$8:$BI$31,2,FALSE) -> 0 | I5: =($H5/7)*8*$I$2 -> 0 | J5: =($H5/7)*9*$J$2 -> 0 | K5: =($H5/7)*10*$K$2 -> 0 | L5: =($H5/7)*11*$L$2 -> 0 | M5: =($H5/7)*12*$M$2 -> 0 | N5: =($H5/7)*13*$N$2 -> 0 | O5: =($H5/7)*14*$O$2 -> 0 | P5: =($H5/7)*15*$P$2 -> 0
A6: =PRICING!A11 -> SSMS | B6: =($H6/7)*$B$2 -> 0 | C6: =($H6/7)*2*$C$2 -> 0 | D6: =($H6/7)*3*$D$2 -> 0 | E6: =($H6/7)*4*$E$2 -> 0 | F6: =($H6/7)*5*$F$2 -> 0 | G6: =($H6/7)*6*$G$2 -> 0 | H6: =VLOOKUP(A6,PRICING!$A$8:$BI$31,2,FALSE) -> 0 | I6: =($H6/7)*8*$I$2 -> 0 | J6: =($H6/7)*9*$J$2 -> 0 | K6: =($H6/7)*10*$K$2 -> 0 | L6: =($H6/7)*11*$L$2 -> 0 | M6: =($H6/7)*12*$M$2 -> 0 | N6: =($H6/7)*13*$N$2 -> 0 | O6: =($H6/7)*14*$O$2 -> 0 | P6: =($H6/7)*15*$P$2 -> 0
A7: =PRICING!A12 -> PMMS | B7: =($H7/7)*$B$2 -> 0 | C7: =($H7/7)*2*$C$2 -> 0 | D7: =($H7/7)*3*$D$2 -> 0 | E7: =($H7/7)*4*$E$2 -> 0 | F7: =($H7/7)*5*$F$2 -> 0 | G7: =($H7/7)*6*$G$2 -> 0 | H7: =VLOOKUP(A7,PRICING!$A$8:$BI$31,2,FALSE) -> 0 | I7: =($H7/7)*8*$I$2 -> 0 | J7: =($H7/7)*9*$J$2 -> 0 | K7: =($H7/7)*10*$K$2 -> 0 | L7: =($H7/7)*11*$L$2 -> 0 | M7: =($H7/7)*12*$M$2 -> 0 | N7: =($H7/7)*13*$N$2 -> 0 | O7: =($H7/7)*14*$O$2 -> 0 | P7: =($H7/7)*15*$P$2 -> 0
A8: =PRICING!A13 -> EMAS | B8: =($H8/7)*$B$2 -> 0 | C8: =($H8/7)*2*$C$2 -> 0 | D8: =($H8/7)*3*$D$2 -> 0 | E8: =($H8/7)*4*$E$2 -> 0 | F8: =($H8/7)*5*$F$2 -> 0 | G8: =($H8/7)*6*$G$2 -> 0 | H8: =VLOOKUP(A8,PRICING!$A$8:$BI$31,2,FALSE) -> 0 | I8: =($H8/7)*8*$I$2 -> 0 | J8: =($H8/7)*9*$J$2 -> 0 | K8: =($H8/7)*10*$K$2 -> 0 | L8: =($H8/7)*11*$L$2 -> 0 | M8: =($H8/7)*12*$M$2 -> 0 | N8: =($H8/7)*13*$N$2 -> 0 | O8: =($H8/7)*14*$O$2 -> 0 | P8: =($H8/7)*15*$P$2 -> 0
A9: =PRICING!A14 -> PSAS | B9: =($H9/7)*$B$2 -> 0 | C9: =($H9/7)*2*$C$2 -> 0 | D9: =($H9/7)*3*$D$2 -> 0 | E9: =($H9/7)*4*$E$2 -> 0 | F9: =($H9/7)*5*$F$2 -> 0 | G9: =($H9/7)*6*$G$2 -> 0 | H9: =VLOOKUP(A9,PRICING!$A$8:$BI$31,2,FALSE) -> 0 | I9: =($H9/7)*8*$I$2 -> 0 | J9: =($H9/7)*9*$J$2 -> 0 | K9: =($H9/7)*10*$K$2 -> 0 | L9: =($H9/7)*11*$L$2 -> 0 | M9: =($H9/7)*12*$M$2 -> 0 | N9: =($H9/7)*13*$N$2 -> 0 | O9: =($H9/7)*14*$O$2 -> 0 | P9: =($H9/7)*15*$P$2 -> 0
A10: =PRICING!A15 -> SSAS | B10: =($H10/7)*$B$2 -> 0 | C10: =($H10/7)*2*$C$2 -> 0 | D10: =($H10/7)*3*$D$2 -> 0 | E10: =($H10/7)*4*$E$2 -> 0 | F10: =($H10/7)*5*$F$2 -> 0 | G10: =($H10/7)*6*$G$2 -> 0 | H10: =VLOOKUP(A10,PRICING!$A$8:$BI$31,2,FALSE) -> 0 | I10: =($H10/7)*8*$I$2 -> 0 | J10: =($H10/7)*9*$J$2 -> 0 | K10: =($H10/7)*10*$K$2 -> 0 | L10: =($H10/7)*11*$L$2 -> 0 | M10: =($H10/7)*12*$M$2 -> 0 | N10: =($H10/7)*13*$N$2 -> 0 | O10: =($H10/7)*14*$O$2 -> 0 | P10: =($H10/7)*15*$P$2 -> 0
A11: =PRICING!A16 -> PMAS | B11: =($H11/7)*$B$2 -> 0 | C11: =($H11/7)*2*$C$2 -> 0 | D11: =($H11/7)*3*$D$2 -> 0 | E11: =($H11/7)*4*$E$2 -> 0 | F11: =($H11/7)*5*$F$2 -> 0 | G11: =($H11/7)*6*$G$2 -> 0 | H11: =VLOOKUP(A11,PRICING!$A$8:$BI$31,2,FALSE) -> 0 | I11: =($H11/7)*8*$I$2 -> 0 | J11: =($H11/7)*9*$J$2 -> 0 | K11: =($H11/7)*10*$K$2 -> 0 | L11: =($H11/7)*11*$L$2 -> 0 | M11: =($H11/7)*12*$M$2 -> 0 | N11: =($H11/7)*13*$N$2 -> 0 | O11: =($H11/7)*14*$O$2 -> 0 | P11: =($H11/7)*15*$P$2 -> 0
A12: =PRICING!A17 -> CMAS | B12: =($H12/7)*$B$2 -> 0 | C12: =($H12/7)*2*$C$2 -> 0 | D12: =($H12/7)*3*$D$2 -> 0 | E12: =($H12/7)*4*$E$2 -> 0 | F12: =($H12/7)*5*$F$2 -> 0 | G12: =($H12/7)*6*$G$2 -> 0 | H12: =VLOOKUP(A12,PRICING!$A$8:$BI$31,2,FALSE) -> 0 | I12: =($H12/7)*8*$I$2 -> 0 | J12: =($H12/7)*9*$J$2 -> 0 | K12: =($H12/7)*10*$K$2 -> 0 | L12: =($H12/7)*11*$L$2 -> 0 | M12: =($H12/7)*12*$M$2 -> 0 | N12: =($H12/7)*13*$N$2 -> 0 | O12: =($H12/7)*14*$O$2 -> 0 | P12: =($H12/7)*15*$P$2 -> 0
A13: =PRICING!A18 -> SMAS | B13: =($H13/7)*$B$2 -> 0 | C13: =($H13/7)*2*$C$2 -> 0 | D13: =($H13/7)*3*$D$2 -> 0 | E13: =($H13/7)*4*$E$2 -> 0 | F13: =($H13/7)*5*$F$2 -> 0 | G13: =($H13/7)*6*$G$2 -> 0 | H13: =VLOOKUP(A13,PRICING!$A$8:$BI$31,2,FALSE) -> 0 | I13: =($H13/7)*8*$I$2 -> 0 | J13: =($H13/7)*9*$J$2 -> 0 | K13: =($H13/7)*10*$K$2 -> 0 | L13: =($H13/7)*11*$L$2 -> 0 | M13: =($H13/7)*12*$M$2 -> 0 | N13: =($H13/7)*13*$N$2 -> 0 | O13: =($H13/7)*14*$O$2 -> 0 | P13: =($H13/7)*15*$P$2 -> 0
A14: =PRICING!D6 -> 0 | B14: 1 day | C14: 2 day | D14: 3 day | E14: 4 day | F14: 5 day | G14: 6 day | H14: 7 day | I14: 8 day | J14: 9 day | K14: 10 day | L14: 11 day | M14: 12 day | N14: 13 day | O14: 14 day | P14: 15 day
A15: =PRICING!D7 -> 0 | B15: 1.75 | C15: 1.5 | D15: 1.41 | E15: 1 | F15: 1 | G15: 1 | H15: 1 | I15: 1 | J15: 1 | K15: 1 | L15: 1 | M15: 1 | N15: 1 | O15: 1 | P15: 1
A16: =A3 -> ESMS | B16: =($H16/7)*$B$15 -> 0 | C16: =($H16/7)*2*$C$15 -> 0 | D16: =($H16/7)*3*$D$15 -> 0 | E16: =($H16/7)*4*$E$15 -> 0 | F16: =($H16/7)*5*$F$15 -> 0 | G16: =($H16/7)*6*$G$15 -> 0 | H16: =VLOOKUP(A16,PRICING!$A$8:$BI$31,4,FALSE) -> 0 | I16: =($H16/7)*8*$I$15 -> 0 | J16: =($H16/7)*9*$J$15 -> 0 | K16: =($H16/7)*10*$K$15 -> 0 | L16: =($H16/7)*11*$L$15 -> 0 | M16: =($H16/7)*12*$M$15 -> 0 | N16: =($H16/7)*13*$N$15 -> 0 | O16: =($H16/7)*14*$O$15 -> 0 | P16: =($H16/7)*15*$P$15 -> 0
A17: =A4 -> EMMS | B17: =($H17/7)*$B$15 -> 0 | C17: =($H17/7)*2*$C$15 -> 0 | D17: =($H17/7)*3*$D$15 -> 0 | E17: =($H17/7)*4*$E$15 -> 0 | F17: =($H17/7)*5*$F$15 -> 0 | G17: =($H17/7)*6*$G$15 -> 0 | H17: =VLOOKUP(A17,PRICING!$A$8:$BI$31,4,FALSE) -> 0 | I17: =($H17/7)*8*$I$15 -> 0 | J17: =($H17/7)*9*$J$15 -> 0 | K17: =($H17/7)*10*$K$15 -> 0 | L17: =($H17/7)*11*$L$15 -> 0 | M17: =($H17/7)*12*$M$15 -> 0 | N17: =($H17/7)*13*$N$15 -> 0 | O17: =($H17/7)*14*$O$15 -> 0 | P17: =($H17/7)*15*$P$15 -> 0
A18: =A5 -> PSMS | B18: =($H18/7)*$B$15 -> 0 | C18: =($H18/7)*2*$C$15 -> 0 | D18: =($H18/7)*3*$D$15 -> 0 | E18: =($H18/7)*4*$E$15 -> 0 | F18: =($H18/7)*5*$F$15 -> 0 | G18: =($H18/7)*6*$G$15 -> 0 | H18: =VLOOKUP(A18,PRICING!$A$8:$BI$31,4,FALSE) -> 0 | I18: =($H18/7)*8*$I$15 -> 0 | J18: =($H18/7)*9*$J$15 -> 0 | K18: =($H18/7)*10*$K$15 -> 0 | L18: =($H18/7)*11*$L$15 -> 0 | M18: =($H18/7)*12*$M$15 -> 0 | N18: =($H18/7)*13*$N$15 -> 0 | O18: =($H18/7)*14*$O$15 -> 0 | P18: =($H18/7)*15*$P$15 -> 0
A19: =A6 -> SSMS | B19: =($H19/7)*$B$15 -> 0 | C19: =($H19/7)*2*$C$15 -> 0 | D19: =($H19/7)*3*$D$15 -> 0 | E19: =($H19/7)*4*$E$15 -> 0 | F19: =($H19/7)*5*$F$15 -> 0 | G19: =($H19/7)*6*$G$15 -> 0 | H19: =VLOOKUP(A19,PRICING!$A$8:$BI$31,4,FALSE) -> 0 | I19: =($H19/7)*8*$I$15 -> 0 | J19: =($H19/7)*9*$J$15 -> 0 | K19: =($H19/7)*10*$K$15 -> 0 | L19: =($H19/7)*11*$L$15 -> 0 | M19: =($H19/7)*12*$M$15 -> 0 | N19: =($H19/7)*13*$N$15 -> 0 | O19: =($H19/7)*14*$O$15 -> 0 | P19: =($H19/7)*15*$P$15 -> 0
A20: =A7 -> PMMS | B20: =($H20/7)*$B$15 -> 0 | C20: =($H20/7)*2*$C$15 -> 0 | D20: =($H20/7)*3*$D$15 -> 0 | E20: =($H20/7)*4*$E$15 -> 0 | F20: =($H20/7)*5*$F$15 -> 0 | G20: =($H20/7)*6*$G$15 -> 0 | H20: =VLOOKUP(A20,PRICING!$A$8:$BI$31,4,FALSE) -> 0 | I20: =($H20/7)*8*$I$15 -> 0 | J20: =($H20/7)*9*$J$15 -> 0 | K20: =($H20/7)*10*$K$15 -> 0 | L20: =($H20/7)*11*$L$15 -> 0 | M20: =($H20/7)*12*$M$15 -> 0 | N20: =($H20/7)*13*$N$15 -> 0 | O20: =($H20/7)*14*$O$15 -> 0 | P20: =($H20/7)*15*$P$15 -> 0
A21: =A8 -> EMAS | B21: =($H21/7)*$B$15 -> 0 | C21: =($H21/7)*2*$C$15 -> 0 | D21: =($H21/7)*3*$D$15 -> 0 | E21: =($H21/7)*4*$E$15 -> 0 | F21: =($H21/7)*5*$F$15 -> 0 | G21: =($H21/7)*6*$G$15 -> 0 | H21: =VLOOKUP(A21,PRICING!$A$8:$BI$31,4,FALSE) -> 0 | I21: =($H21/7)*8*$I$15 -> 0 | J21: =($H21/7)*9*$J$15 -> 0 | K21: =($H21/7)*10*$K$15 -> 0 | L21: =($H21/7)*11*$L$15 -> 0 | M21: =($H21/7)*12*$M$15 -> 0 | N21: =($H21/7)*13*$N$15 -> 0 | O21: =($H21/7)*14*$O$15 -> 0 | P21: =($H21/7)*15*$P$15 -> 0
A22: =A9 -> PSAS | B22: =($H22/7)*$B$15 -> 0 | C22: =($H22/7)*2*$C$15 -> 0 | D22: =($H22/7)*3*$D$15 -> 0 | E22: =($H22/7)*4*$E$15 -> 0 | F22: =($H22/7)*5*$F$15 -> 0 | G22: =($H22/7)*6*$G$15 -> 0 | H22: =VLOOKUP(A22,PRICING!$A$8:$BI$31,4,FALSE) -> 0 | I22: =($H22/7)*8*$I$15 -> 0 | J22: =($H22/7)*9*$J$15 -> 0 | K22: =($H22/7)*10*$K$15 -> 0 | L22: =($H22/7)*11*$L$15 -> 0 | M22: =($H22/7)*12*$M$15 -> 0 | N22: =($H22/7)*13*$N$15 -> 0 | O22: =($H22/7)*14*$O$15 -> 0 | P22: =($H22/7)*15*$P$15 -> 0
A23: =A10 -> SSAS | B23: =($H23/7)*$B$15 -> 0 | C23: =($H23/7)*2*$C$15 -> 0 | D23: =($H23/7)*3*$D$15 -> 0 | E23: =($H23/7)*4*$E$15 -> 0 | F23: =($H23/7)*5*$F$15 -> 0 | G23: =($H23/7)*6*$G$15 -> 0 | H23: =VLOOKUP(A23,PRICING!$A$8:$BI$31,4,FALSE) -> 0 | I23: =($H23/7)*8*$I$15 -> 0 | J23: =($H23/7)*9*$J$15 -> 0 | K23: =($H23/7)*10*$K$15 -> 0 | L23: =($H23/7)*11*$L$15 -> 0 | M23: =($H23/7)*12*$M$15 -> 0 | N23: =($H23/7)*13*$N$15 -> 0 | O23: =($H23/7)*14*$O$15 -> 0 | P23: =($H23/7)*15*$P$15 -> 0
A24: =A11 -> PMAS | B24: =($H24/7)*$B$15 -> 0 | C24: =($H24/7)*2*$C$15 -> 0 | D24: =($H24/7)*3*$D$15 -> 0 | E24: =($H24/7)*4*$E$15 -> 0 | F24: =($H24/7)*5*$F$15 -> 0 | G24: =($H24/7)*6*$G$15 -> 0 | H24: =VLOOKUP(A24,PRICING!$A$8:$BI$31,4,FALSE) -> 0 | I24: =($H24/7)*8*$I$15 -> 0 | J24: =($H24/7)*9*$J$15 -> 0 | K24: =($H24/7)*10*$K$15 -> 0 | L24: =($H24/7)*11*$L$15 -> 0 | M24: =($H24/7)*12*$M$15 -> 0 | N24: =($H24/7)*13*$N$15 -> 0 | O24: =($H24/7)*14*$O$15 -> 0 | P24: =($H24/7)*15*$P$15 -> 0
A25: =A12 -> CMAS | B25: =($H25/7)*$B$15 -> 0 | C25: =($H25/7)*2*$C$15 -> 0 | D25: =($H25/7)*3*$D$15 -> 0 | E25: =($H25/7)*4*$E$15 -> 0 | F25: =($H25/7)*5*$F$15 -> 0 | G25: =($H25/7)*6*$G$15 -> 0 | H25: =VLOOKUP(A25,PRICING!$A$8:$BI$31,4,FALSE) -> 0 | I25: =($H25/7)*8*$I$15 -> 0 | J25: =($H25/7)*9*$J$15 -> 0 | K25: =($H25/7)*10*$K$15 -> 0 | L25: =($H25/7)*11*$L$15 -> 0 | M25: =($H25/7)*12*$M$15 -> 0 | N25: =($H25/7)*13*$N$15 -> 0 | O25: =($H25/7)*14*$O$15 -> 0 | P25: =($H25/7)*15*$P$15 -> 0
A26: =A13 -> SMAS | B26: =($H26/7)*$B$15 -> 0 | C26: =($H26/7)*2*$C$15 -> 0 | D26: =($H26/7)*3*$D$15 -> 0 | E26: =($H26/7)*4*$E$15 -> 0 | F26: =($H26/7)*5*$F$15 -> 0 | G26: =($H26/7)*6*$G$15 -> 0 | H26: =VLOOKUP(A26,PRICING!$A$8:$BI$31,4,FALSE) -> 0 | I26: =($H26/7)*8*$I$15 -> 0 | J26: =($H26/7)*9*$J$15 -> 0 | K26: =($H26/7)*10*$K$15 -> 0 | L26: =($H26/7)*11*$L$15 -> 0 | M26: =($H26/7)*12*$M$15 -> 0 | N26: =($H26/7)*13*$N$15 -> 0 | O26: =($H26/7)*14*$O$15 -> 0 | P26: =($H26/7)*15*$P$15 -> 0
A27: =PRICING!F6 -> 0 | B27: 1 day | C27: 2 day | D27: 3 day | E27: 4 day | F27: 5 day | G27: 6 day | H27: 7 day | I27: 8 day | J27: 9 day | K27: 10 day | L27: 11 day | M27: 12 day | N27: 13 day | O27: 14 day | P27: 15 day
A28: =PRICING!F7 -> 0 | B28: 2.27 | C28: 1.4 | D28: 1.31 | E28: 1 | F28: 1 | G28: 1 | H28: 1 | I28: 1 | J28: 1 | K28: 1 | L28: 1 | M28: 1 | N28: 1 | O28: 1 | P28: 1
A29: =A16 -> ESMS | B29: =($H29/7)*$B$28 -> 0 | C29: =($H29/7)*2*$C$28 -> 0 | D29: =($H29/7)*3*$D$28 -> 0 | E29: =($H29/7)*4*$E$28 -> 0 | F29: =($H29/7)*5*$F$28 -> 0 | G29: =($H29/7)*6*$G$28 -> 0 | H29: =VLOOKUP(A29,PRICING!$A$8:$BI$31,6,FALSE) -> 0 | I29: =($H29/7)*8*$I$28 -> 0 | J29: =($H29/7)*9*$J$28 -> 0 | K29: =($H29/7)*10*$K$28 -> 0 | L29: =($H29/7)*11*$L$28 -> 0 | M29: =($H29/7)*12*$M$28 -> 0 | N29: =($H29/7)*13*$N$28 -> 0 | O29: =($H29/7)*14*$O$28 -> 0 | P29: =($H29/7)*15*$P$28 -> 0
A30: =A17 -> EMMS | B30: =($H30/7)*$B$28 -> 0 | C30: =($H30/7)*2*$C$28 -> 0 | D30: =($H30/7)*3*$D$28 -> 0 | E30: =($H30/7)*4*$E$28 -> 0 | F30: =($H30/7)*5*$F$28 -> 0 | G30: =($H30/7)*6*$G$28 -> 0 | H30: =VLOOKUP(A30,PRICING!$A$8:$BI$31,6,FALSE) -> 0 | I30: =($H30/7)*8*$I$28 -> 0 | J30: =($H30/7)*9*$J$28 -> 0 | K30: =($H30/7)*10*$K$28 -> 0 | L30: =($H30/7)*11*$L$28 -> 0 | M30: =($H30/7)*12*$M$28 -> 0 | N30: =($H30/7)*13*$N$28 -> 0 | O30: =($H30/7)*14*$O$28 -> 0 | P30: =($H30/7)*15*$P$28 -> 0
A31: =A18 -> PSMS | B31: =($H31/7)*$B$28 -> 0 | C31: =($H31/7)*2*$C$28 -> 0 | D31: =($H31/7)*3*$D$28 -> 0 | E31: =($H31/7)*4*$E$28 -> 0 | F31: =($H31/7)*5*$F$28 -> 0 | G31: =($H31/7)*6*$G$28 -> 0 | H31: =VLOOKUP(A31,PRICING!$A$8:$BI$31,6,FALSE) -> 0 | I31: =($H31/7)*8*$I$28 -> 0 | J31: =($H31/7)*9*$J$28 -> 0 | K31: =($H31/7)*10*$K$28 -> 0 | L31: =($H31/7)*11*$L$28 -> 0 | M31: =($H31/7)*12*$M$28 -> 0 | N31: =($H31/7)*13*$N$28 -> 0 | O31: =($H31/7)*14*$O$28 -> 0 | P31: =($H31/7)*15*$P$28 -> 0
A32: =A19 -> SSMS | B32: =($H32/7)*$B$28 -> 0 | C32: =($H32/7)*2*$C$28 -> 0 | D32: =($H32/7)*3*$D$28 -> 0 | E32: =($H32/7)*4*$E$28 -> 0 | F32: =($H32/7)*5*$F$28 -> 0 | G32: =($H32/7)*6*$G$28 -> 0 | H32: =VLOOKUP(A32,PRICING!$A$8:$BI$31,6,FALSE) -> 0 | I32: =($H32/7)*8*$I$28 -> 0 | J32: =($H32/7)*9*$J$28 -> 0 | K32: =($H32/7)*10*$K$28 -> 0 | L32: =($H32/7)*11*$L$28 -> 0 | M32: =($H32/7)*12*$M$28 -> 0 | N32: =($H32/7)*13*$N$28 -> 0 | O32: =($H32/7)*14*$O$28 -> 0 | P32: =($H32/7)*15*$P$28 -> 0
A33: =A20 -> PMMS | B33: =($H33/7)*$B$28 -> 0 | C33: =($H33/7)*2*$C$28 -> 0 | D33: =($H33/7)*3*$D$28 -> 0 | E33: =($H33/7)*4*$E$28 -> 0 | F33: =($H33/7)*5*$F$28 -> 0 | G33: =($H33/7)*6*$G$28 -> 0 | H33: =VLOOKUP(A33,PRICING!$A$8:$BI$31,6,FALSE) -> 0 | I33: =($H33/7)*8*$I$28 -> 0 | J33: =($H33/7)*9*$J$28 -> 0 | K33: =($H33/7)*10*$K$28 -> 0 | L33: =($H33/7)*11*$L$28 -> 0 | M33: =($H33/7)*12*$M$28 -> 0 | N33: =($H33/7)*13*$N$28 -> 0 | O33: =($H33/7)*14*$O$28 -> 0 | P33: =($H33/7)*15*$P$28 -> 0
A34: =A21 -> EMAS | B34: =($H34/7)*$B$28 -> 0 | C34: =($H34/7)*2*$C$28 -> 0 | D34: =($H34/7)*3*$D$28 -> 0 | E34: =($H34/7)*4*$E$28 -> 0 | F34: =($H34/7)*5*$F$28 -> 0 | G34: =($H34/7)*6*$G$28 -> 0 | H34: =VLOOKUP(A34,PRICING!$A$8:$BI$31,6,FALSE) -> 0 | I34: =($H34/7)*8*$I$28 -> 0 | J34: =($H34/7)*9*$J$28 -> 0 | K34: =($H34/7)*10*$K$28 -> 0 | L34: =($H34/7)*11*$L$28 -> 0 | M34: =($H34/7)*12*$M$28 -> 0 | N34: =($H34/7)*13*$N$28 -> 0 | O34: =($H34/7)*14*$O$28 -> 0 | P34: =($H34/7)*15*$P$28 -> 0
A35: =A22 -> PSAS | B35: =($H35/7)*$B$28 -> 0 | C35: =($H35/7)*2*$C$28 -> 0 | D35: =($H35/7)*3*$D$28 -> 0 | E35: =($H35/7)*4*$E$28 -> 0 | F35: =($H35/7)*5*$F$28 -> 0 | G35: =($H35/7)*6*$G$28 -> 0 | H35: =VLOOKUP(A35,PRICING!$A$8:$BI$31,6,FALSE) -> 0 | I35: =($H35/7)*8*$I$28 -> 0 | J35: =($H35/7)*9*$J$28 -> 0 | K35: =($H35/7)*10*$K$28 -> 0 | L35: =($H35/7)*11*$L$28 -> 0 | M35: =($H35/7)*12*$M$28 -> 0 | N35: =($H35/7)*13*$N$28 -> 0 | O35: =($H35/7)*14*$O$28 -> 0 | P35: =($H35/7)*15*$P$28 -> 0
A36: =A23 -> SSAS | B36: =($H36/7)*$B$28 -> 0 | C36: =($H36/7)*2*$C$28 -> 0 | D36: =($H36/7)*3*$D$28 -> 0 | E36: =($H36/7)*4*$E$28 -> 0 | F36: =($H36/7)*5*$F$28 -> 0 | G36: =($H36/7)*6*$G$28 -> 0 | H36: =VLOOKUP(A36,PRICING!$A$8:$BI$31,6,FALSE) -> 0 | I36: =($H36/7)*8*$I$28 -> 0 | J36: =($H36/7)*9*$J$28 -> 0 | K36: =($H36/7)*10*$K$28 -> 0 | L36: =($H36/7)*11*$L$28 -> 0 | M36: =($H36/7)*12*$M$28 -> 0 | N36: =($H36/7)*13*$N$28 -> 0 | O36: =($H36/7)*14*$O$28 -> 0 | P36: =($H36/7)*15*$P$28 -> 0
A37: =A24 -> PMAS | B37: =($H37/7)*$B$28 -> 0 | C37: =($H37/7)*2*$C$28 -> 0 | D37: =($H37/7)*3*$D$28 -> 0 | E37: =($H37/7)*4*$E$28 -> 0 | F37: =($H37/7)*5*$F$28 -> 0 | G37: =($H37/7)*6*$G$28 -> 0 | H37: =VLOOKUP(A37,PRICING!$A$8:$BI$31,6,FALSE) -> 0 | I37: =($H37/7)*8*$I$28 -> 0 | J37: =($H37/7)*9*$J$28 -> 0 | K37: =($H37/7)*10*$K$28 -> 0 | L37: =($H37/7)*11*$L$28 -> 0 | M37: =($H37/7)*12*$M$28 -> 0 | N37: =($H37/7)*13*$N$28 -> 0 | O37: =($H37/7)*14*$O$28 -> 0 | P37: =($H37/7)*15*$P$28 -> 0
A38: =A25 -> CMAS | B38: =($H38/7)*$B$28 -> 0 | C38: =($H38/7)*2*$C$28 -> 0 | D38: =($H38/7)*3*$D$28 -> 0 | E38: =($H38/7)*4*$E$28 -> 0 | F38: =($H38/7)*5*$F$28 -> 0 | G38: =($H38/7)*6*$G$28 -> 0 | H38: =VLOOKUP(A38,PRICING!$A$8:$BI$31,6,FALSE) -> 0 | I38: =($H38/7)*8*$I$28 -> 0 | J38: =($H38/7)*9*$J$28 -> 0 | K38: =($H38/7)*10*$K$28 -> 0 | L38: =($H38/7)*11*$L$28 -> 0 | M38: =($H38/7)*12*$M$28 -> 0 | N38: =($H38/7)*13*$N$28 -> 0 | O38: =($H38/7)*14*$O$28 -> 0 | P38: =($H38/7)*15*$P$28 -> 0
A39: =A26 -> SMAS | B39: =($H39/7)*$B$28 -> 0 | C39: =($H39/7)*2*$C$28 -> 0 | D39: =($H39/7)*3*$D$28 -> 0 | E39: =($H39/7)*4*$E$28 -> 0 | F39: =($H39/7)*5*$F$28 -> 0 | G39: =($H39/7)*6*$G$28 -> 0 | H39: =VLOOKUP(A39,PRICING!$A$8:$BI$31,6,FALSE) -> 0 | I39: =($H39/7)*8*$I$28 -> 0 | J39: =($H39/7)*9*$J$28 -> 0 | K39: =($H39/7)*10*$K$28 -> 0 | L39: =($H39/7)*11*$L$28 -> 0 | M39: =($H39/7)*12*$M$28 -> 0 | N39: =($H39/7)*13*$N$28 -> 0 | O39: =($H39/7)*14*$O$28 -> 0 | P39: =($H39/7)*15*$P$28 -> 0
A40: =PRICING!H6 -> 0 | B40: 1 day | C40: 2 day | D40: 3 day | E40: 4 day | F40: 5 day | G40: 6 day | H40: 7 day | I40: 8 day | J40: 9 day | K40: 10 day | L40: 11 day | M40: 12 day | N40: 13 day | O40: 14 day | P40: 15 day
...
